<?xml version="1.0" ?>
<!-- =================================================================================== -->
<!-- |    This document was autogenerated by xacro from monopod.urdf.xacro             | -->
<!-- |    EDITING THIS FILE BY HAND IS NOT RECOMMENDED                                 | -->
<!-- =================================================================================== -->
<robot name="monopod" xmlns:xacro="http://ros.org/wiki/xacro">
  <!-- Cube base -->
  <link name="base_link">
    <inertial>
      <origin rpy="0 0 0" xyz="0 0 0.5"/>
      <mass value="2.0"/>
      <inertia ixx="0.0133" ixy="0.0" ixz="0.0" iyy="0.0133" iyz="0.0" izz="0.0133"/>
    </inertial>
    <visual>
      <origin rpy="0 0 0" xyz="0 0 0.5"/>
      <geometry>
        <mesh filename="package://meshes/cube_body.dae"/>
      </geometry>
      <material name="base_color">
        <color rgba="0.8 0.2 0.2 1.0"/>
      </material>
    </visual>
    <collision>
      <origin rpy="0 0 0" xyz="0 0 0.5"/>
      <geometry>
        <mesh filename="package://meshes/cube_body.dae"/>
      </geometry>
    </collision>
  </link>
  <!-- Joint 1: Pitch (X-axis) -->
  <joint name="joint_pitch" type="revolute">
    <parent link="base_link"/>
    <child link="intermediate_link"/>
    <origin rpy="0 0 0" xyz="0 0 -0.1"/>
    <axis xyz="1 0 0"/>
    <limit effort="10" lower="-1.57" upper="1.57" velocity="1.0"/>
  </joint>
  <!-- Intermediate link for universal joint -->
  <link name="intermediate_link">
    <inertial>
      <origin rpy="0 0 0" xyz="0 0 0"/>
      <mass value="0.001"/>
      <inertia ixx="1e-6" ixy="0" ixz="0" iyy="1e-6" iyz="0" izz="1e-6"/>
    </inertial>
  </link>
  <!-- Joint 2: Roll (Y-axis) -->
  <joint name="joint_roll" type="revolute">
    <parent link="intermediate_link"/>
    <child link="leg_link"/>
    <origin rpy="0 0 0" xyz="0 0 0"/>
    <axis xyz="0 1 0"/>
    <limit effort="10" lower="-1.57" upper="1.57" velocity="1.0"/>
  </joint>
  <!-- Cylindrical leg -->
  <link name="leg_link">
    <inertial>
      <origin rpy="0 0 0" xyz="0 0 0.1"/>
      <mass value="1.0"/>
      <inertia ixx="0.00104" ixy="0.0" ixz="0.0" iyy="0.00104" iyz="0.0" izz="0.00005"/>
    </inertial>
    <visual>
      <origin rpy="0 0 0" xyz="0 0 0.1"/>
      <geometry>
        <mesh filename="package://meshes/cylindrical_leg.dae"/>
      </geometry>
      <material name="leg_color">
        <color rgba="0.2 0.8 0.2 1.0"/>
      </material>
    </visual>
    <collision>
      <origin rpy="0 0 0" xyz="0 0 0.1"/>
      <geometry>
        <mesh filename="package://meshes/cylindrical_leg.dae"/>
      </geometry>
    </collision>
  </link>
</robot>

